<?xml version="1.0"?>
<robot name="agv_model"
	xmlns:xacro="http://ros.org/wiki/xacro">

	<xacro:property name="M_PI" value="3.1415926" />
	<xacro:property name="H_PI" value="1.5707963" />

    <link name="base_link">
        <visual>
                <geometry>
                    <box size="1e-6 1e-6 1e-6"/>
                </geometry>
            <origin xyz="0 0 0" rpy="0 0 0"/>
            <material name="white">
                <color rgba="1 1 1 1"/>
            </material>
        </visual>
        <collision>
            <geometry>
                    <box size="1e-6 1e-6 1e-6"/>
            </geometry>
        </collision>
        <inertial>
            <mass value="1e-6"/>
            <inertia ixx="1.0" ixy="0.0" ixz="0.0" iyy="1.0" iyz="0.0" izz="1.0"/>
        </inertial>
    </link>

    <link name="base_ment_link">
        <visual>
                <geometry>
                    <box size="1 0.6 0.2"/>
                </geometry>
            <origin xyz="0 0 0" rpy="0 0 0"/>
            <material name="white">
                <color rgba="1 1 1 1"/>
            </material>
        </visual>
        <collision>
            <geometry>
                    <box size="1 0.6 0.2"/>
            </geometry>
        </collision>
        <inertial>
            <mass value="1"/>
            <inertia ixx="1.0" ixy="0.0" ixz="0.0" iyy="1.0" iyz="0.0" izz="1.0"/>
        </inertial>
    </link>

    <joint name="base_ment_link_to_base_link_joint" type="fixed">
        <parent link="base_link"/>
        <child link="base_ment_link"/>
        <origin xyz="0 0 0.2" rpy="0 0 0"/>
    </joint>

    <link name="laser_link">
        <collision>
            <origin xyz="0 0 0.025" rpy="0 0 0" />
            <geometry>
                <box size="0.03 0.03 0.05" />
            </geometry>
        </collision>
        <visual>
            <origin xyz="0 0 0.025" rpy="0 0 0" />
            <geometry>
                <box size="0.03 0.03 0.05" />
            </geometry>
            <material name="green">
                <color rgba="0 1 0 1"/>
            </material>
        </visual>
        <inertial>
            <mass value="1e-5" />
            <origin xyz="0 0 0" rpy="0 0 0" />
            <inertia ixx="1e-6" ixy="0" ixz="0" iyy="1e6" iyz="0" izz="1e-6" />
        </inertial>
    </link>

    <joint name="laser_joint" type="fixed">
        <origin xyz="0.515 0 0" rpy=" 0 0 0" />
        <parent link="base_ment_link" />
        <child link="laser_link" />
    </joint>

    <gazebo reference="laser_link">
        <sensor name= "hokuyo" type="gpu_ray">
            <pose>0 0 0 0 0 0</pose>
            <visualize>false</visualize>
            <update_rate>10</update_rate>
            <ray>
                <scan>
                    <horizontal>
                        <samples>720</samples>
                        <resolution>1</resolution>
                        <min_angle>-1.570796</min_angle>
                        <max_angle>1.570796</max_angle>
                    </horizontal>
                </scan>
                <range>
                    <min>0.01</min>
                    <max>30.0</max>
                    <resolution>0.01</resolution>
                </range>
            </ray>
            <plugin name="gpu_laser" filename="libgazebo_ros_gpu_laser.so">
                <topicName>/agv_scan</topicName>
                <frameName>/agv_laser</frameName>
            </plugin>
        </sensor>
    </gazebo>

    <link name="charge_base_link">
        <collision>
            <origin xyz="0 0 0" rpy="0 0 0" />
            <geometry>
                <box size="1e-6 1e-6 1e-6" />
            </geometry>
        </collision>
        <visual>
            <origin xyz="0 0 0" rpy="0 0 0" />
            <geometry>
                <box size="1e-6 1e-6 1e-6" />
            </geometry>
            <material name="red">
                <color rgba="1 0 0 1"/>
            </material>
        </visual>
        <inertial>
            <mass value="1e-5" />
            <origin xyz="0 0 0" rpy="0 0 0" />
            <inertia ixx="1e-6" ixy="0" ixz="0" iyy="1e6" iyz="0" izz="1e-6" />
        </inertial>
    </link>

    <joint name="charge_base_link_to_base_ment_link_joint" type="fixed">
        <origin xyz="-0.5 0 0" rpy=" 0 0 0" />
        <parent link="base_ment_link" />
        <child link="charge_base_link" />
    </joint>

    <link name="box_top_link">
        <collision>
            <origin xyz="0 0 0" rpy="0 0 0" />
            <geometry>
                <box size="0.1 0.4 0.005" />
            </geometry>
        </collision>
        <visual>
            <origin xyz="0 0 0" rpy="0 0 0" />
            <geometry>
                <box size="0.1 0.4 0.005" />
            </geometry>
            <material name="red">
                <color rgba="1 0 0 1"/>
            </material>
        </visual>
        <inertial>
            <mass value="1e-5" />
            <origin xyz="0 0 0" rpy="0 0 0" />
            <inertia ixx="1e-6" ixy="0" ixz="0" iyy="1e6" iyz="0" izz="1e-6" />
        </inertial>
    </link>

    <joint name="box_top_link_to_charge_base_link_joint" type="fixed">
        <origin xyz="-0.055 0 0.0525" rpy=" 0 0 0" />
        <parent link="charge_base_link" />
        <child link="box_top_link" />
    </joint>

    <link name="box_bottom_link">
        <collision>
            <origin xyz="0 0 0" rpy="0 0 0" />
            <geometry>
                <box size="0.1 0.4 0.005" />
            </geometry>
        </collision>
        <visual>
            <origin xyz="0 0 0" rpy="0 0 0" />
            <geometry>
                <box size="0.1 0.4 0.005" />
            </geometry>
            <material name="red">
                <color rgba="1 0 0 1"/>
            </material>
        </visual>
        <inertial>
            <mass value="1e-5" />
            <origin xyz="0 0 0" rpy="0 0 0" />
            <inertia ixx="1e-6" ixy="0" ixz="0" iyy="1e6" iyz="0" izz="1e-6" />
        </inertial>
    </link>

    <joint name="box_bottom_link_to_charge_base_link_joint" type="fixed">
        <origin xyz="-0.055 0 -0.0525" rpy=" 0 0 0" />
        <parent link="charge_base_link" />
        <child link="box_bottom_link" />
    </joint>

    <link name="box_left_link">
        <collision>
            <origin xyz="0 0 0" rpy="0 0 0" />
            <geometry>
                <box size="0.1 0.005 0.1" />
            </geometry>
        </collision>
        <visual>
            <origin xyz="0 0 0" rpy="0 0 0" />
            <geometry>
                <box size="0.1 0.005 0.1" />
            </geometry>
            <material name="red">
                <color rgba="1 0 0 1"/>
            </material>
        </visual>
        <inertial>
            <mass value="1e-5" />
            <origin xyz="0 0 0" rpy="0 0 0" />
            <inertia ixx="1e-6" ixy="0" ixz="0" iyy="1e6" iyz="0" izz="1e-6" />
        </inertial>
    </link>

    <joint name="box_left_link_to_charge_base_link_joint" type="fixed">
        <origin xyz="-0.055 0.1975 0" rpy=" 0 0 0" />
        <parent link="charge_base_link" />
        <child link="box_left_link" />
    </joint>

    <link name="box_right_link">
        <collision>
            <origin xyz="0 0 0" rpy="0 0 0" />
            <geometry>
                <box size="0.1 0.005 0.1" />
            </geometry>
        </collision>
        <visual>
            <origin xyz="0 0 0" rpy="0 0 0" />
            <geometry>
                <box size="0.1 0.005 0.1" />
            </geometry>
            <material name="red">
                <color rgba="1 0 0 1"/>
            </material>
        </visual>
        <inertial>
            <mass value="1e-5" />
            <origin xyz="0 0 0" rpy="0 0 0" />
            <inertia ixx="1e-6" ixy="0" ixz="0" iyy="1e6" iyz="0" izz="1e-6" />
        </inertial>
    </link>

    <joint name="box_right_link_to_charge_base_link_joint" type="fixed">
        <origin xyz="-0.055 -0.1975 0" rpy=" 0 0 0" />
        <parent link="charge_base_link" />
        <child link="box_right_link" />
    </joint>

    <link name="box_back_link">
        <collision>
            <origin xyz="0 0 0" rpy="0 0 0" />
            <geometry>
                <box size="0.005 0.4 0.1" />
            </geometry>
        </collision>
        <visual>
            <origin xyz="0 0 0" rpy="0 0 0" />
            <geometry>
                <box size="0.005 0.4 0.1" />
            </geometry>
            <material name="red">
                <color rgba="1 0 0 1"/>
            </material>
        </visual>
        <inertial>
            <mass value="1e-5" />
            <origin xyz="0 0 0" rpy="0 0 0" />
            <inertia ixx="1e-6" ixy="0" ixz="0" iyy="1e6" iyz="0" izz="1e-6" />
        </inertial>
    </link>

    <joint name="box_back_link_to_charge_base_link_joint" type="fixed">
        <origin xyz="-0.0025 0 0" rpy=" 0 0 0" />
        <parent link="charge_base_link" />
        <child link="box_back_link" />
    </joint>

    <link name="baffle_A_link">
        <collision>
            <origin xyz="0 0 0" rpy="0 0 0" />
            <geometry>
                <box size="0.005 0.04 0.1" />
            </geometry>
        </collision>
        <visual>
            <origin xyz="0 0 0" rpy="0 0 0" />
            <geometry>
                <box size="0.005 0.04 0.1" />
            </geometry>
            <material name="blue">
                <color rgba="0 0 1 1"/>
            </material>
        </visual>
        <inertial>
            <mass value="1e-5" />
            <origin xyz="0 0 0" rpy="0 0 0" />
            <inertia ixx="1e-6" ixy="0" ixz="0" iyy="1e6" iyz="0" izz="1e-6" />
        </inertial>
    </link>

    <joint name="baffle_A_link_to_charge_base_link_joint" type="fixed">
        <origin xyz="-0.1 -0.125 0" rpy=" 0 0 0" />
        <parent link="charge_base_link" />
        <child link="baffle_A_link" />
    </joint>

    <link name="baffle_B_link">
        <collision>
            <origin xyz="0 0 0" rpy="0 0 0" />
            <geometry>
                <box size="0.005 0.05 0.1" />
            </geometry>
        </collision>
        <visual>
            <origin xyz="0 0 0" rpy="0 0 0" />
            <geometry>
                <box size="0.005 0.05 0.1" />
            </geometry>
            <material name="blue">
                <color rgba="0 0 1 1"/>
            </material>
        </visual>
        <inertial>
            <mass value="1e-5" />
            <origin xyz="0 0 0" rpy="0 0 0" />
            <inertia ixx="1e-6" ixy="0" ixz="0" iyy="1e6" iyz="0" izz="1e-6" />
        </inertial>
    </link>

    <joint name="baffle_B_link_to_charge_base_link_joint" type="fixed">
        <origin xyz="-0.1 -0.05 0" rpy=" 0 0 0" />
        <parent link="charge_base_link" />
        <child link="baffle_B_link" />
    </joint>

    <link name="baffle_C_link">
        <collision>
            <origin xyz="0 0 0" rpy="0 0 0" />
            <geometry>
                <box size="0.005 0.04 0.1" />
            </geometry>
        </collision>
        <visual>
            <origin xyz="0 0 0" rpy="0 0 0" />
            <geometry>
                <box size="0.005 0.04 0.1" />
            </geometry>
            <material name="blue">
                <color rgba="0 0 1 1"/>
            </material>
        </visual>
        <inertial>
            <mass value="1e-5" />
            <origin xyz="0 0 0" rpy="0 0 0" />
            <inertia ixx="1e-6" ixy="0" ixz="0" iyy="1e6" iyz="0" izz="1e-6" />
        </inertial>
    </link>

    <joint name="baffle_C_link_to_charge_base_link_joint" type="fixed">
        <origin xyz="-0.1 0.025 0" rpy=" 0 0 0" />
        <parent link="charge_base_link" />
        <child link="baffle_C_link" />
    </joint>

    <link name="baffle_D_link">
        <collision>
            <origin xyz="0 0 0" rpy="0 0 0" />
            <geometry>
                <box size="0.005 0.07 0.1" />
            </geometry>
        </collision>
        <visual>
            <origin xyz="0 0 0" rpy="0 0 0" />
            <geometry>
                <box size="0.005 0.07 0.1" />
            </geometry>
            <material name="blue">
                <color rgba="0 0 1 1"/>
            </material>
        </visual>
        <inertial>
            <mass value="1e-5" />
            <origin xyz="0 0 0" rpy="0 0 0" />
            <inertia ixx="1e-6" ixy="0" ixz="0" iyy="1e6" iyz="0" izz="1e-6" />
        </inertial>
    </link>

    <joint name="baffle_D_link_to_charge_base_link_joint" type="fixed">
        <origin xyz="-0.1 0.11 0" rpy=" 0 0 0" />
        <parent link="charge_base_link" />
        <child link="baffle_D_link" />
    </joint>

    <link name="baffle_left_link">
        <collision>
            <origin xyz="0 0 0" rpy="0 0 0" />
            <geometry>
                <box size="0.005 0.02 0.1" />
            </geometry>
        </collision>
        <visual>
            <origin xyz="0 0 0" rpy="0 0 0" />
            <geometry>
                <box size="0.005 0.02 0.1" />
            </geometry>
            <material name="red">
                <color rgba="1 0 0 1"/>
            </material>
        </visual>
        <inertial>
            <mass value="1e-5" />
            <origin xyz="0 0 0" rpy="0 0 0" />
            <inertia ixx="1e-6" ixy="0" ixz="0" iyy="1e6" iyz="0" izz="1e-6" />
        </inertial>
    </link>

    <joint name="baffle_left_link_to_charge_base_link_joint" type="fixed">
        <origin xyz="-0.1 0.185 0" rpy=" 0 0 0" />
        <parent link="charge_base_link" />
        <child link="baffle_left_link" />
    </joint>

    <link name="baffle_right_link">
        <collision>
            <origin xyz="0 0 0" rpy="0 0 0" />
            <geometry>
                <box size="0.005 0.02 0.1" />
            </geometry>
        </collision>
        <visual>
            <origin xyz="0 0 0" rpy="0 0 0" />
            <geometry>
                <box size="0.005 0.02 0.1" />
            </geometry>
            <material name="red">
                <color rgba="1 0 0 1"/>
            </material>
        </visual>
        <inertial>
            <mass value="1e-5" />
            <origin xyz="0 0 0" rpy="0 0 0" />
            <inertia ixx="1e-6" ixy="0" ixz="0" iyy="1e6" iyz="0" izz="1e-6" />
        </inertial>
    </link>

    <joint name="baffle_right_link_to_charge_base_link_joint" type="fixed">
        <origin xyz="-0.1 -0.185 0" rpy=" 0 0 0" />
        <parent link="charge_base_link" />
        <child link="baffle_right_link" />
    </joint>

    <link name="font_left_wheel_link">
        <visual>
                <geometry>
                    <cylinder length="0.05" radius="0.2"/>
                </geometry>
            <origin xyz="0 0 0" rpy="0 0 0"/>
            <material name="white">
                <color rgba="1 1 1 1"/>
            </material>
        </visual>
        <collision>
            <geometry>
                    <cylinder length="0.05" radius="0.2"/>
            </geometry>
        </collision>
        <inertial>
            <mass value="0.1"/>
            <inertia ixx="1.0" ixy="0.0" ixz="0.0" iyy="1.0" iyz="0.0" izz="1.0"/>
        </inertial>
    </link>

    <joint name="font_left_wheel_link_to_base_ment_link_joint" type="continuous">
        <parent link="base_ment_link"/>
        <child link="font_left_wheel_link"/>
        <origin xyz="0.42 0.325 0" rpy="-1.57 0 0"/>
        <axis xyz="0 0 1"/>
    </joint>

    <link name="font_right_wheel_link">
        <visual>
                <geometry>
                    <cylinder length="0.05" radius="0.2"/>
                </geometry>
            <origin xyz="0 0 0" rpy="0 0 0"/>
            <material name="white">
                <color rgba="1 1 1 1"/>
            </material>
        </visual>
        <collision>
            <geometry>
                    <cylinder length="0.05" radius="0.2"/>
            </geometry>
        </collision>
        <inertial>
            <mass value="0.1"/>
            <inertia ixx="1.0" ixy="0.0" ixz="0.0" iyy="1.0" iyz="0.0" izz="1.0"/>
        </inertial>
    </link>

    <joint name="font_right_wheel_link_to_base_ment_link_joint" type="continuous">
        <parent link="base_ment_link"/>
        <child link="font_right_wheel_link"/>
        <origin xyz="0.42 -0.325 0" rpy="-1.57 0 0"/>
        <axis xyz="0 0 1"/>
    </joint>

     <link name="middle_left_wheel_link">
        <visual>
                <geometry>
                    <cylinder length="0.05" radius="0.2"/>
                </geometry>
            <origin xyz="0 0 0" rpy="0 0 0"/>
            <material name="white">
                <color rgba="1 1 1 1"/>
            </material>
        </visual>
        <collision>
            <geometry>
                    <cylinder length="0.05" radius="0.2"/>
            </geometry>
        </collision>
        <inertial>
            <mass value="0.1"/>
            <inertia ixx="1.0" ixy="0.0" ixz="0.0" iyy="1.0" iyz="0.0" izz="1.0"/>
        </inertial>
    </link>

    <joint name="middle_left_wheel_link_to_base_ment_link_joint" type="continuous">
        <parent link="base_ment_link"/>
        <child link="middle_left_wheel_link"/>
        <origin xyz="0 0.325 0" rpy="-1.57 0 0"/>
        <axis xyz="0 0 1"/>
    </joint>

    <link name="middle_right_wheel_link">
        <visual>
                <geometry>
                    <cylinder length="0.05" radius="0.2"/>
                </geometry>
            <origin xyz="0 0 0" rpy="0 0 0"/>
            <material name="white">
                <color rgba="1 1 1 1"/>
            </material>
        </visual>
        <collision>
            <geometry>
                    <cylinder length="0.05" radius="0.2"/>
            </geometry>
        </collision>
        <inertial>
            <mass value="0.1"/>
            <inertia ixx="1.0" ixy="0.0" ixz="0.0" iyy="1.0" iyz="0.0" izz="1.0"/>
        </inertial>
    </link>

    <joint name="middle_right_wheel_link_to_base_ment_link_joint" type="continuous">
        <parent link="base_ment_link"/>
        <child link="middle_right_wheel_link"/>
        <origin xyz="0 -0.325 0" rpy="-1.57 0 0"/>
        <axis xyz="0 0 1"/>
    </joint>

     <link name="back_left_wheel_link">
        <visual>
                <geometry>
                    <cylinder length="0.05" radius="0.2"/>
                </geometry>
            <origin xyz="0 0 0" rpy="0 0 0"/>
            <material name="white">
                <color rgba="1 1 1 1"/>
            </material>
        </visual>
        <collision>
            <geometry>
                    <cylinder length="0.05" radius="0.2"/>
            </geometry>
        </collision>
        <inertial>
            <mass value="0.1"/>
            <inertia ixx="1.0" ixy="0.0" ixz="0.0" iyy="1.0" iyz="0.0" izz="1.0"/>
        </inertial>
    </link>

    <joint name="back_left_wheel_link_to_base_ment_link_joint" type="continuous">
        <parent link="base_ment_link"/>
        <child link="back_left_wheel_link"/>
        <origin xyz="-0.42 0.325 0" rpy="-1.57 0 0"/>
        <axis xyz="0 0 1"/>
    </joint>

    <link name="back_right_wheel_link">
        <visual>
                <geometry>
                    <cylinder length="0.05" radius="0.2"/>
                </geometry>
            <origin xyz="0 0 0" rpy="0 0 0"/>
            <material name="white">
                <color rgba="1 1 1 1"/>
            </material>
        </visual>
        <collision>
            <geometry>
                    <cylinder length="0.05" radius="0.2"/>
            </geometry>
        </collision>
        <inertial>
            <mass value="0.1"/>
            <inertia ixx="1.0" ixy="0.0" ixz="0.0" iyy="1.0" iyz="0.0" izz="1.0"/>
        </inertial>
    </link>

    <joint name="back_right_wheel_link_to_base_ment_link_joint" type="continuous">
        <parent link="base_ment_link"/>
        <child link="back_right_wheel_link"/>
        <origin xyz="-0.42 -0.325 0" rpy="-1.57 0 0"/>
        <axis xyz="0 0 1"/>
    </joint>

    <link name="charge_plugin_base_link">
        <visual>
                <geometry>
                    <box size="1e-5 1e-5 1e-5"/>
                </geometry>
            <origin xyz="0 0 0" rpy="0 0 0"/>
            <material name="white">
                <color rgba="1 1 1 1"/>
            </material>
        </visual>
        <collision>
            <geometry>
                    <box size="1e-5 1e-5 1e-5"/>
            </geometry>
        </collision>
        <inertial>
            <mass value="0.1"/>
            <inertia ixx="1.0" ixy="0.0" ixz="0.0" iyy="1.0" iyz="0.0" izz="1.0"/>
        </inertial>
    </link>

    <joint name="charge_plugin_base_link_to_charge_base_link_joint" type="fixed">
        <parent link="charge_base_link"/>
        <child link="charge_plugin_base_link"/>
        <origin xyz="-0.055 0 0.055" rpy="0 -1.57 0"/>
    </joint>

    <link name="charge_plugin_back_link">
        <visual>
                <geometry>
                    <box size="0.005 0.02 0.02"/>
                </geometry>
            <origin xyz="0 0 0" rpy="0 0 0"/>
            <material name="white">
                <color rgba="1 1 1 1"/>
            </material>
        </visual>
        <collision>
            <geometry>
                    <box size="0.005 0.02 0.02"/>
            </geometry>
        </collision>
        <inertial>
            <mass value="0.1"/>
            <inertia ixx="1.0" ixy="0.0" ixz="0.0" iyy="1.0" iyz="0.0" izz="1.0"/>
        </inertial>
    </link>

    <joint name="charge_plugin_back_link_to_charge_plugin_base_link_joint" type="fixed">
        <parent link="charge_plugin_base_link"/>
        <child link="charge_plugin_back_link"/>
        <origin xyz="0.0025 0 0" rpy="0 0 0"/>
    </joint>

    <link name="charge_plugin_top_link">
        <visual>
                <geometry>
                    <box size="0.04 0.03 0.005"/>
                </geometry>
            <origin xyz="0 0 0" rpy="0 0 0"/>
            <material name="white">
                <color rgba="1 1 1 1"/>
            </material>
        </visual>
        <collision>
            <geometry>
                    <box size="0.04 0.03 0.005"/>
            </geometry>
        </collision>
        <inertial>
            <mass value="0.1"/>
            <inertia ixx="1.0" ixy="0.0" ixz="0.0" iyy="1.0" iyz="0.0" izz="1.0"/>
        </inertial>
    </link>

    <joint name="charge_plugin_top_link_to_charge_plugin_base_link_joint" type="fixed">
        <parent link="charge_plugin_base_link"/>
        <child link="charge_plugin_top_link"/>
        <origin xyz="0.02 0 0.0125" rpy="0 0 0"/>
    </joint>

    <link name="charge_plugin_bottom_link">
        <visual>
                <geometry>
                    <box size="0.04 0.03 0.005"/>
                </geometry>
            <origin xyz="0 0 0" rpy="0 0 0"/>
            <material name="white">
                <color rgba="1 1 1 1"/>
            </material>
        </visual>
        <collision>
            <geometry>
                    <box size="0.04 0.03 0.005"/>
            </geometry>
        </collision>
        <inertial>
            <mass value="0.1"/>
            <inertia ixx="1.0" ixy="0.0" ixz="0.0" iyy="1.0" iyz="0.0" izz="1.0"/>
        </inertial>
    </link>

    <joint name="charge_plugin_bottom_link_to_charge_plugin_base_link_joint" type="fixed">
        <parent link="charge_plugin_base_link"/>
        <child link="charge_plugin_bottom_link"/>
        <origin xyz="0.02 0 -0.0125" rpy="0 0 0"/>
    </joint>

    <link name="charge_plugin_left_link">
        <visual>
                <geometry>
                    <box size="0.04 0.005 0.03"/>
                </geometry>
            <origin xyz="0 0 0" rpy="0 0 0"/>
            <material name="white">
                <color rgba="1 1 1 1"/>
            </material>
        </visual>
        <collision>
            <geometry>
                    <box size="0.04 0.005 0.03"/>
            </geometry>
        </collision>
        <inertial>
            <mass value="0.1"/>
            <inertia ixx="1.0" ixy="0.0" ixz="0.0" iyy="1.0" iyz="0.0" izz="1.0"/>
        </inertial>
    </link>

    <joint name="charge_plugin_left_link_to_charge_plugin_base_link_joint" type="fixed">
        <parent link="charge_plugin_base_link"/>
        <child link="charge_plugin_left_link"/>
        <origin xyz="0.02 0.0125 0" rpy="0 0 0"/>
    </joint>

    <link name="charge_plugin_right_link">
        <visual>
                <geometry>
                    <box size="0.04 0.005 0.03"/>
                </geometry>
            <origin xyz="0 0 0" rpy="0 0 0"/>
            <material name="white">
                <color rgba="1 1 1 1"/>
            </material>
        </visual>
        <collision>
            <geometry>
                    <box size="0.04 0.005 0.03"/>
            </geometry>
        </collision>
        <inertial>
            <mass value="0.1"/>
            <inertia ixx="1.0" ixy="0.0" ixz="0.0" iyy="1.0" iyz="0.0" izz="1.0"/>
        </inertial>
    </link>

    <joint name="charge_plugin_right_link_to_charge_plugin_base_link_joint" type="fixed">
        <parent link="charge_plugin_base_link"/>
        <child link="charge_plugin_right_link"/>
        <origin xyz="0.02 -0.0125 0" rpy="0 0 0"/>
    </joint>

    <gazebo>
        <plugin name="differential_drive_controller"
            filename="libgazebo_ros_diff_drive.so">
            <leftJoint>middle_left_wheel_link_to_base_ment_link_joint</leftJoint>
            <rightJoint>middle_right_wheel_link_to_base_ment_link_joint</rightJoint>
            <robotBaseFrame>base_ment_link</robotBaseFrame>
            <wheelSeparation>0.2</wheelSeparation>
            <wheelDiameter>0.65</wheelDiameter>
            <publishWheelJointState>true</publishWheelJointState>
            <legacyMode>false<legacyMode>
            <commandTopic>/agv_cmd_vel</commandTopic>
            <odometryTopic>/agv_odom</odometryTopic>
        </plugin>
    </gazebo>
</robot>